<?xml version="1.0" ?>
<sdf version='1.6'>
  <model name='Cr450'>
      <link name='base_link'>
        <pose> 0 0 0.084993 0 -0 0</pose>
        <inertial>
          <pose>0 0 0.018225 0 -0 0</pose>
          <mass>2.212</mass>
          <inertia>
            <ixx>0.0226756</ixx>
            <ixy>3.97681e-06</ixy>
            <ixz>0.000108111</ixz>
            <iyy>0.0266242</iyy>
            <iyz>-3.04273e-05</iyz>
            <izz>0.0376656</izz>
          </inertia>
        </inertial>
        <collision name='base_link_collision'>
          <pose>0 0 0 0 -0 0</pose>
          <!-- <geometry>
            <mesh>
              <scale>1 1 1</scale>
              <uri>model://Crp450/meshes/base_link.STL</uri>
            </mesh>
          </geometry> -->
          <geometry>
            <box>
              <size>0.32 0.32 0.165</size>
            </box>
          </geometry>
          <max_contacts>3</max_contacts>
          <surface>
            <contact>
              <ode/>
            </contact>
            <bounce/>
            <friction>
              <torsional>
                <ode/>
              </torsional>
              <ode/>
            </friction>
          </surface>
        </collision>
        <!-- <collision name='base_link_fixed_joint_lump__Arm_base_collision_1'>
          <pose>0.000642 0 0 0 -0 0</pose>
          <geometry>
            <mesh>
              <scale>1 1 1</scale>
              <uri>model://Crp450/meshes/Arm_base.STL</uri>
            </mesh>
          </geometry>
          <max_contacts>4</max_contacts>
          <surface>
            <contact>
              <ode/>
            </contact>
            <bounce/>
            <friction>
              <torsional>
                <ode/>
              </torsional>
              <ode/>
            </friction>
          </surface>
        </collision> -->
        <visual name='base_link_visual'>
          <pose>0 0 0 0 -0 0</pose>
          <geometry>
            <mesh>
              <scale>1 1 1</scale>
              <uri>model://Crp450/meshes/base_link.STL</uri>
            </mesh>
          </geometry>
          <material>
          <script>
            <name>Gazebo/BlackTransparent</name>
            <uri>file://media/materials/scripts/gazebo.material</uri>
          </script>
        </material>
        </visual>
        <visual name='base_link_fixed_joint_lump__Arm_base_visual_1'>
          <pose>0.000642 0 0 0 -0 0</pose>
          <geometry>
            <mesh>
              <scale>1 1 1</scale>
              <uri>model://Crp450/meshes/Arm_base.STL</uri>
            </mesh>
          </geometry>
          <material>
            <script>
              <name>Gazebo/Green</name>
              <uri>file://media/materials/scripts/gazebo.material</uri>
            </script>
          </material>
        </visual>
        <self_collide>0</self_collide>
        <enable_wind>0</enable_wind>
        <kinematic>0</kinematic>
      </link>
      <link name='/imu_link'>
        <pose>0 0 0.02 0 0 0</pose>
        <inertial>
          <pose>0 0 0 0 0 0</pose>
          <mass>0.015</mass>
          <inertia>
            <ixx>1e-05</ixx>
            <ixy>0</ixy>
            <ixz>0</ixz>
            <iyy>1e-05</iyy>
            <iyz>0</iyz>
            <izz>1e-05</izz>
          </inertia>
        </inertial>
      </link>
      <joint name='/imu_joint' type='revolute'>
        <child>/imu_link</child>
        <parent>base_link</parent>
        <axis>
          <xyz>1 0 0</xyz>
          <limit>
            <lower>0</lower>
            <upper>0</upper>
            <effort>0</effort>
            <velocity>0</velocity>
          </limit>
          <dynamics>
            <spring_reference>0</spring_reference>
            <spring_stiffness>0</spring_stiffness>
          </dynamics>
          <use_parent_model_frame>1</use_parent_model_frame>
        </axis>
      </joint>


      <joint name='BL_blade_joint' type='revolute'>
        <pose relative_to='base_link'>-0.1591 0.1591 0.0717 0 -0 0</pose>
        <parent>base_link</parent>
        <child>BL_blade</child>
        <axis>
          <xyz>0 0 1</xyz>
          <limit>
            <lower>-1e+16</lower>
            <upper>1e+16</upper>
          </limit>
          <dynamics>
            <spring_reference>0</spring_reference>
            <spring_stiffness>0</spring_stiffness>
          </dynamics>
        </axis>
      </joint>
      <link name='BL_blade'>
        <pose relative_to='BL_blade_joint'>0 0 0 0 -0 0</pose>
        <inertial>
          <pose>0 0 -0.005636 0 -0 0</pose>
          <mass>0.011718</mass>
          <inertia>
            <ixx>2.8885e-05</ixx>
            <ixy>-2.6125e-05</ixy>
            <ixz>-6.7614e-14</ixz>
            <iyy>2.441e-05</iyy>
            <iyz>-3.0842e-13</iyz>
            <izz>5.3207e-05</izz>
          </inertia>
        </inertial>
        <collision name='BL_blade_collision'>
          <pose>0 0 0 0 -0 0</pose>
          <geometry>
            <!-- <mesh>
              <scale>1 1 1</scale>
              <uri>model://Crp450/meshes/BL_blade.STL</uri>
            </mesh> -->
            <cylinder>
              <length>0.005</length>
              <radius>0.2794</radius>
            </cylinder>
          </geometry>
          <max_contacts>4</max_contacts>
          <surface>
            <contact>
              <ode/>
            </contact>
            <bounce/>
            <friction>
              <torsional>
                <ode/>
              </torsional>
              <ode/>
            </friction>
          </surface>
        </collision>
        <visual name='BL_blade_visual'>
          <pose>0 0 0 0 -0 0</pose>
          <geometry>
            <mesh>
              <scale>1 1 1</scale>
              <uri>model://Crp450/meshes/BL_blade.STL</uri>
            </mesh>
          </geometry>
          <material>
            <script>
              <name>Gazebo/RedTransparentOverlay</name>
              <uri>file://media/materials/scripts/gazebo.material</uri>
            </script>
          </material>
        </visual>
        <self_collide>0</self_collide>
        <enable_wind>0</enable_wind>
        <kinematic>0</kinematic>
      </link>
      <joint name='BR_blade_joint' type='revolute'>
        <pose relative_to='base_link'>-0.1591 -0.1591 0.0717 0 -0 0</pose>
        <parent>base_link</parent>
        <child>BR_blade</child>
        <axis>
          <xyz>0 0 1</xyz>
          <limit>
            <lower>-1e+16</lower>
            <upper>1e+16</upper>
          </limit>
          <dynamics>
            <spring_reference>0</spring_reference>
            <spring_stiffness>0</spring_stiffness>
          </dynamics>
        </axis>
      </joint>
      <link name='BR_blade'>
        <pose relative_to='BR_blade_joint'>0 0 0 0 -0 0</pose>
        <inertial>
          <pose>0 -0 -0.005636 0 -0 0</pose>
          <mass>0.011718</mass>
          <inertia>
            <ixx>3.6874e-05</ixx>
            <ixy>2.4145e-05</ixy>
            <ixz>-2.8321e-13</ixz>
            <iyy>1.6421e-05</iyy>
            <iyz>1.4019e-13</iyz>
            <izz>5.3207e-05</izz>
          </inertia>
        </inertial>
        <collision name='BR_blade_collision'>
          <pose>0 0 0 0 -0 0</pose>
          <geometry>
            <!-- <mesh>
              <scale>1 1 1</scale>
              <uri>model://Crp450/meshes/BR_blade.STL</uri>
            </mesh> -->
            <cylinder>
              <length>0.005</length>
              <radius>0.2794</radius>
            </cylinder>
          </geometry>
          <max_contacts>4</max_contacts>
          <surface>
            <contact>
              <ode/>
            </contact>
            <bounce/>
            <friction>
              <torsional>
                <ode/>
              </torsional>
              <ode/>
            </friction>
          </surface>
        </collision>
        <visual name='BR_blade_visual'>
          <pose>0 0 0 0 -0 0</pose>
          <geometry>
            <mesh>
              <scale>1 1 1</scale>
              <uri>model://Crp450/meshes/BR_blade.STL</uri>
            </mesh>
          </geometry>
          <material>
            <script>
              <name>Gazebo/BlueTransparentOverlay</name>
              <uri>file://media/materials/scripts/gazebo.material</uri>
            </script>
          </material>
        </visual>
        <self_collide>0</self_collide>
        <enable_wind>0</enable_wind>
        <kinematic>0</kinematic>
      </link>
      <joint name='FL_blade_joint' type='revolute'>
        <pose relative_to='base_link'>0.1591 0.1591 0.0717 0 -0 0</pose>
        <parent>base_link</parent>
        <child>FL_blade</child>
        <axis>
          <xyz>0 0 1</xyz>
          <limit>
            <lower>-1e+16</lower>
            <upper>1e+16</upper>
          </limit>
          <dynamics>
            <spring_reference>0</spring_reference>
            <spring_stiffness>0</spring_stiffness>
          </dynamics>
        </axis>
      </joint>
      <link name='FL_blade'>
        <pose relative_to='FL_blade_joint'>0 0 0 0 -0 0</pose>
        <inertial>
          <pose>0 -0 -0.005636 0 -0 0</pose>
          <mass>0.011718</mass>
          <inertia>
            <ixx>2.0616e-05</ixx>
            <ixy>2.5518e-05</ixy>
            <ixz>-5.0635e-13</ixz>
            <iyy>3.2679e-05</iyy>
            <iyz>1.8143e-13</iyz>
            <izz>5.3207e-05</izz>
          </inertia>
        </inertial>
        <collision name='FL_blade_collision'>
          <pose>0 0 0 0 -0 0</pose>
          <geometry>
            <!-- <mesh>
              <scale>1 1 1</scale>
              <uri>model://Crp450/meshes/FL_blade.STL</uri>
            </mesh> -->
            <cylinder>
              <length>0.005</length>
              <radius>0.2794</radius>
            </cylinder>
          </geometry>
          <max_contacts>4</max_contacts>
          <surface>
            <contact>
              <ode/>
            </contact>
            <bounce/>
            <friction>
              <torsional>
                <ode/>
              </torsional>
              <ode/>
            </friction>
          </surface>
        </collision>
        <visual name='FL_blade_visual'>
          <pose>0 0 0 0 -0 0</pose>
          <geometry>
            <mesh>
              <scale>1 1 1</scale>
              <uri>model://Crp450/meshes/FL_blade.STL</uri>
            </mesh>
          </geometry>
          <material>
            <script>
              <name>Gazebo/BlueTransparentOverlay</name>
              <uri>file://media/materials/scripts/gazebo.material</uri>
            </script>
          </material>
        </visual>
        <self_collide>0</self_collide>
        <enable_wind>0</enable_wind>
        <kinematic>0</kinematic>
      </link>
      <joint name='FR_blade_joint' type='revolute'>
        <pose relative_to='base_link'>0.1591 -0.1591 0.0717 0 -0 0</pose>
        <parent>base_link</parent>
        <child>FR_blade</child>
        <axis>
          <xyz>0 0 1</xyz>
          <limit>
            <lower>-1e+16</lower>
            <upper>1e+16</upper>
          </limit>
          <dynamics>
            <spring_reference>0</spring_reference>
            <spring_stiffness>0</spring_stiffness>
          </dynamics>
        </axis>
      </joint>
      <link name='FR_blade'>
        <pose relative_to='FR_blade_joint'>0 0 0 0 -0 0</pose>
        <inertial>
          <pose>-0 -0 -0.005636 0 -0 0</pose>
          <mass>0.011718</mass>
          <inertia>
            <ixx>2.7345e-05</ixx>
            <ixy>-2.6212e-05</ixy>
            <ixz>8.0345e-14</ixz>
            <iyy>2.595e-05</iyy>
            <iyz>3.1056e-13</iyz>
            <izz>5.3207e-05</izz>
          </inertia>
        </inertial>
        <collision name='FR_blade_collision'>
          <pose>0 0 0 0 -0 0</pose>
          <geometry>
            <!-- <mesh>
              <scale>1 1 1</scale>
              <uri>model://Crp450/meshes/FR_blade.STL</uri>
            </mesh> -->
            <cylinder>
              <length>0.005</length>
              <radius>0.2794</radius>
            </cylinder>
          </geometry>
          <max_contacts>4</max_contacts>
          <surface>
            <contact>
              <ode/>
            </contact>
            <bounce/>
            <friction>
              <torsional>
                <ode/>
              </torsional>
              <ode/>
            </friction>
          </surface>
        </collision>
        <visual name='FR_blade_visual'>
          <pose>0 0 0 0 -0 0</pose>
          <geometry>
            <mesh>
              <scale>1 1 1</scale>
              <uri>model://Crp450/meshes/FR_blade.STL</uri>
            </mesh>
          </geometry>
          <material>
            <script>
              <name>Gazebo/RedTransparentOverlay</name>
              <uri>file://media/materials/scripts/gazebo.material</uri>
            </script>
          </material>
        </visual>
        <self_collide>0</self_collide>
        <enable_wind>0</enable_wind>
        <kinematic>0</kinematic>
      </link>
      
      <!-- px4 -->
      <!-- <plugin name='rosbag' filename='libgazebo_multirotor_base_plugin.so'>
        <robotNamespace/>
        <linkName>base_link</linkName>
        <rotorVelocitySlowdownSim>10</rotorVelocitySlowdownSim>
      </plugin> -->

      <!-- <entity name="motorParam">
        <timeConstantUp>0.125</timeConstantUp>
        <timeConstantDown>0.025</timeConstantDown>
        <maxRotVelocity>2200</maxRotVelocity>
        <motorConstant>15.68e-06</motorConstant>
        <momentConstant>0.01</momentConstant>
        <commandSubTopic>/gazebo/command/motor_speed</commandSubTopic>
        <rotorDragCoefficient>0.000175</rotorDragCoefficient>
        <rollingMomentCoefficient>1e-06</rollingMomentCoefficient>
        <rotorVelocitySlowdownSim>10</rotorVelocitySlowdownSim>
      </entity> -->

      <entity name="motorParam">
        <timeConstantUp>0.125</timeConstantUp>
        <timeConstantDown>0.025</timeConstantDown>
        <maxRotVelocity>15030</maxRotVelocity>
        <motorConstant>0.0812</motorConstant>
        <momentConstant>0.0106</momentConstant>
        <commandSubTopic>/gazebo/command/motor_speed</commandSubTopic>
        <rotorDragCoefficient>0.143</rotorDragCoefficient>
        <rollingMomentCoefficient>0.00053</rollingMomentCoefficient>
        <rotorVelocitySlowdownSim>10</rotorVelocitySlowdownSim>
      </entity>

      <plugin name='front_right_motor_model' filename='libgazebo_motor_model.so'>
        <robotNamespace/>
        $(motorParam)
        <jointName>FR_blade_joint</jointName>
        <linkName>FR_blade</linkName>
        <turningDirection>ccw</turningDirection>
        <motorNumber>0</motorNumber>
        <motorSpeedPubTopic>/motor_speed/0</motorSpeedPubTopic>
      </plugin>
      <plugin name='back_left_motor_model' filename='libgazebo_motor_model.so'>
        <robotNamespace/>
        $(motorParam)
        <jointName>BL_blade_joint</jointName>
        <linkName>BL_blade</linkName>
        <turningDirection>ccw</turningDirection>
        <motorNumber>1</motorNumber>
        <motorSpeedPubTopic>/motor_speed/1</motorSpeedPubTopic>
      </plugin>
      <plugin name='front_left_motor_model' filename='libgazebo_motor_model.so'>
        <robotNamespace/>
        $(motorParam)
        <jointName>FL_blade_joint</jointName>
        <linkName>FL_blade</linkName>
        <turningDirection>cw</turningDirection>
        <motorNumber>2</motorNumber>
        <motorSpeedPubTopic>/motor_speed/2</motorSpeedPubTopic>
      </plugin>
      <plugin name='back_right_motor_model' filename='libgazebo_motor_model.so'>
        <robotNamespace/>
        $(motorParam)
        <jointName>BR_blade_joint</jointName>
        <linkName>BR_blade</linkName>
        <turningDirection>cw</turningDirection>
        <motorNumber>3</motorNumber>
        <motorSpeedPubTopic>/motor_speed/3</motorSpeedPubTopic>
      </plugin>


      <plugin name='rotors_gazebo_imu_plugin' filename='libgazebo_imu_plugin.so'>
        <robotNamespace/>
        <linkName>/imu_link</linkName>
        <imuTopic>/imu</imuTopic>
        <gyroscopeNoiseDensity>0.00018665</gyroscopeNoiseDensity>
        <gyroscopeRandomWalk>3.8785e-05</gyroscopeRandomWalk>
        <gyroscopeBiasCorrelationTime>1000.0</gyroscopeBiasCorrelationTime>
        <gyroscopeTurnOnBiasSigma>0.0087</gyroscopeTurnOnBiasSigma>
        <accelerometerNoiseDensity>0.00186</accelerometerNoiseDensity>
        <accelerometerRandomWalk>0.006</accelerometerRandomWalk>
        <accelerometerBiasCorrelationTime>300.0</accelerometerBiasCorrelationTime>
        <accelerometerTurnOnBiasSigma>0.196</accelerometerTurnOnBiasSigma>
      </plugin>
      <include>
        <uri>model://gps</uri>
        <pose>0.05 0 0.04 0 0 0</pose>
        <name>gps0</name>
      </include>
      <joint name='gps0_joint' type='fixed'>
        <child>gps0::link</child>
        <parent>base_link</parent>
      </joint>
      <plugin name='groundtruth_plugin' filename='libgazebo_groundtruth_plugin.so'>
        <robotNamespace/>
      </plugin>
      <plugin name='magnetometer_plugin' filename='libgazebo_magnetometer_plugin.so'>
        <robotNamespace/>
        <pubRate>100</pubRate>
        <noiseDensity>0.0004</noiseDensity>
        <randomWalk>6.4e-06</randomWalk>
        <biasCorrelationTime>600</biasCorrelationTime>
        <magTopic>/mag</magTopic>
      </plugin>
      <plugin name='barometer_plugin' filename='libgazebo_barometer_plugin.so'>
        <robotNamespace/>
        <pubRate>50</pubRate>
        <baroTopic>/baro</baroTopic>
        <baroDriftPaPerSec>0</baroDriftPaPerSec>
      </plugin>


      <plugin name='mavlink_interface' filename='libgazebo_mavlink_interface.so'>
        <robotNamespace/>
        <imuSubTopic>/imu</imuSubTopic>
        <magSubTopic>/mag</magSubTopic>
        <baroSubTopic>/baro</baroSubTopic>
        <mavlink_addr>INADDR_ANY</mavlink_addr>
        <mavlink_tcp_port>4560</mavlink_tcp_port>
        <mavlink_udp_port>14560</mavlink_udp_port>
        <serialEnabled>0</serialEnabled>
        <serialDevice>/dev/ttyACM0</serialDevice>
        <baudRate>921600</baudRate>
        <qgc_addr>INADDR_ANY</qgc_addr>
        <qgc_udp_port>14550</qgc_udp_port>
        <sdk_addr>INADDR_ANY</sdk_addr>
        <sdk_udp_port>14540</sdk_udp_port>
        <hil_mode>0</hil_mode>
        <hil_state_level>0</hil_state_level>
        <send_vision_estimation>0</send_vision_estimation>
        <send_odometry>1</send_odometry>
        <enable_lockstep>1</enable_lockstep>
        <use_tcp>1</use_tcp>
        <motorSpeedCommandPubTopic>/gazebo/command/motor_speed</motorSpeedCommandPubTopic>
        <control_channels>
          <channel name='rotor1'>
            <input_index>0</input_index>
            <input_offset>0</input_offset>
            <input_scaling>1000</input_scaling>
            <zero_position_disarmed>0</zero_position_disarmed>
            <zero_position_armed>100</zero_position_armed>
            <joint_control_type>velocity</joint_control_type>
          </channel>
          <channel name='rotor2'>
            <input_index>1</input_index>
            <input_offset>0</input_offset>
            <input_scaling>1000</input_scaling>
            <zero_position_disarmed>0</zero_position_disarmed>
            <zero_position_armed>100</zero_position_armed>
            <joint_control_type>velocity</joint_control_type>
          </channel>
          <channel name='rotor3'>
            <input_index>2</input_index>
            <input_offset>0</input_offset>
            <input_scaling>1000</input_scaling>
            <zero_position_disarmed>0</zero_position_disarmed>
            <zero_position_armed>100</zero_position_armed>
            <joint_control_type>velocity</joint_control_type>
          </channel>
          <channel name='rotor4'>
            <input_index>3</input_index>
            <input_offset>0</input_offset>
            <input_scaling>1000</input_scaling>
            <zero_position_disarmed>0</zero_position_disarmed>
            <zero_position_armed>100</zero_position_armed>
            <joint_control_type>velocity</joint_control_type>
          </channel>
        </control_channels>
      </plugin>


      <!-- <joint name='Arm1_joint' type='revolute'> -->
      <joint name='Arm1_joint' type='fixed'>
        <pose relative_to='base_link'>0.00775 0.00025 -0.04 0 -0 0</pose>
        <parent>base_link</parent>
        <child>Arm1</child>
        <axis>
          <xyz>0 -1 0</xyz>
          <limit>
            <lower>-1e+16</lower>
            <upper>1e+16</upper>
          </limit>
          <dynamics>
            <spring_reference>0</spring_reference>
            <spring_stiffness>0</spring_stiffness>
          </dynamics>
        </axis>
        <velocity>10</velocity>
      </joint>
      <link name='Arm1'>
        <pose relative_to='Arm1_joint'>0 0 0 0 -0 0</pose>
        <inertial>
          <pose>-0.060375 8.6e-05 -0.014312 0 -0 0</pose>
          <mass>0.031972</mass>
          <inertia>
            <ixx>4.5666e-06</ixx>
            <ixy>2.3617e-21</ixy>
            <ixz>-1.0416e-05</ixz>
            <iyy>4.9543e-05</iyy>
            <iyz>5.4084e-22</iyz>
            <izz>4.6037e-05</izz>
          </inertia>
        </inertial>
        <!-- <collision name='Arm1_collision'>
          <pose>0 0 0 0 -0 0</pose>
          <geometry>
            <mesh>
              <scale>1 1 1</scale>
              <uri>model://Crp450/meshes/Arm1.STL</uri>
            </mesh>
          </geometry>
          <max_contacts>4</max_contacts>
          <surface>
            <contact>
              <ode/>
            </contact>
            <bounce/>
            <friction>
              <torsional>
                <ode/>
              </torsional>
              <ode/>
            </friction>
          </surface>
        </collision> -->
        <visual name='Arm1_visual'>
          <pose>0 0 0 0 -0 0</pose>
          <geometry>
            <mesh>     
              <scale>1 1 1</scale>
              <uri>model://Crp450/meshes/Arm1.STL</uri>
            </mesh>
          </geometry>
          <material>
            <script>
              <name>Gazebo/White</name>
              <uri>file://media/materials/scripts/gazebo.material</uri>
            </script>
          </material>
        </visual>
        <self_collide>0</self_collide>
        <enable_wind>0</enable_wind>
        <kinematic>0</kinematic>
      </link>
      <joint name='Arm2_joint' type='revolute'>
        <pose relative_to='Arm1'>-0.116764 0 -0.027678 0 -0 0</pose>
        <parent>Arm1</parent>
        <child>Arm2</child>
        <axis>
          <xyz>0 -1 0</xyz>
          <limit>
            <lower>-1e+16</lower>
            <upper>1e+16</upper>
          </limit>
          <dynamics>
            <spring_reference>0</spring_reference>
            <spring_stiffness>0</spring_stiffness>
          </dynamics>
        </axis>

        <velocity>10</velocity>
      </joint>
      <link name='Arm2'>
        <pose relative_to='Arm2_joint'>0 0 0 0 -0 0</pose>
        <inertial>
          <pose>0.140639 -0 -6e-05 0 -0 0</pose>
          <mass>0.134922</mass>
          <inertia>
            <ixx>9.80992e-05</ixx>
            <ixy>-1.70274e-19</ixy>
            <ixz>5.18243e-07</ixz>
            <iyy>0.00105258</iyy>
            <iyz>2.41411e-21</iyz>
            <izz>0.00114513</izz>
          </inertia>
        </inertial>
        <!-- <collision name='Arm2_collision'>
          <pose>0 0 0 0 -0 0</pose>
          <geometry>
            <mesh>
              <scale>1 1 1</scale>
              <uri>model://Crp450/meshes/Arm2.STL</uri>
            </mesh>
          </geometry>
          <max_contacts>4</max_contacts>
          <surface>
            <contact>
              <ode/>
            </contact>
            <bounce/>
            <friction>
              <torsional>
                <ode/>
              </torsional>
              <ode/>
            </friction>
          </surface>
        </collision> -->
        <!-- <collision name='Arm2_fixed_joint_lump__bat_collision_1'>
          <pose>0.213156 0 0.0019 0 -0 0</pose>
          <geometry>
            <mesh>
              <scale>1 1 1</scale>
              <uri>model://Crp450/meshes/bat.STL</uri>
            </mesh>
          </geometry>
          <max_contacts>4</max_contacts>
          <surface>
            <contact>
              <ode/>
            </contact>
            <bounce/>
            <friction>
              <torsional>
                <ode/>
              </torsional>
              <ode/>
            </friction>
          </surface>
        </collision> -->
        <visual name='Arm2_visual'>
          <pose>0 0 0 0 -0 0</pose>
          <geometry>
            <mesh>
              <scale>1 1 1</scale>
              <uri>model://Crp450/meshes/Arm2.STL</uri>
            </mesh>
          </geometry>
          <material>
            <script>
              <name>Gazebo/FlatBlack</name>
              <uri>file://media/materials/scripts/gazebo.material</uri>
            </script>
          </material>
        </visual>
        <visual name='Arm2_fixed_joint_lump__bat_visual_1'>
          <pose>0.213156 0 0.0019 0 -0 0</pose>
          <geometry>
            <mesh>
              <scale>1 1 1</scale>
              <uri>model://Crp450/meshes/bat.STL</uri>
            </mesh>
          </geometry>
          <material>
            <script>
              <name>Gazebo/RedBright</name>
              <uri>file://media/materials/scripts/gazebo.material</uri>
            </script>
          </material>
        </visual>
        <self_collide>0</self_collide>
        <enable_wind>0</enable_wind>
        <kinematic>0</kinematic>
      </link>
      <plugin name="arm_1_controller" filename="libjoint_plugin.so">
        <jointname>Arm1_joint</jointname>
      </plugin>
      <plugin name="arm_2_controller" filename="libjoint_plugin.so">
        <jointname>Arm2_joint</jointname>
      </plugin>

      <pose>0 0 0 0 -0 0</pose>
      <static>0</static>
    </model>
</sdf>
